Workbook

Sheet Read Me
A1: DCFdesk — Multi Commodity Exchange of India Ltd (MCX)
A2: Day 16 · 30 Days of AI Finance · Based on real public financials (Screener.in, FY26 TTM) · ₹ Crores
B4: WHAT THIS IS
B5: A three-scenario DCF on MCX (NSE: MCX), India's commodity derivatives exchange monopoly. Built from FY26 TTM financials (Screener.in, BSE/NSE filings). All figures in ₹ Crores.
B7: WHY MCX IS DIFFERENT FROM A TYPICAL DCF SUBJECT
B8: 1. NET CASH, NOT NET DEBT. MCX has ₹2,944 Cr of net cash (Investments ₹2,949 Cr − Borrowings ₹5 Cr). This ADDS to equity value (EV + Net Cash = Equity), not subtracts.
B9: 2. MONOPOLY EXCHANGE. 95.9% commodity derivatives market share. Revenue = transaction fees on ADTV. Cost base is largely fixed — hence 70%+ EBITDA margins at peak.
B10: 3. FY26 IS A REBOUND YEAR. FY24 was depressed (₹83 Cr net profit) due to platform migration. FY26 revenue ₹2,302 Cr (up 107% on FY25). Projections model future growth from this elevated base.
B12: DATA SOURCES
B13: Revenue, EBITDA, D&A: Screener.in · FY26 TTM (Mar 2026)
B14: Capex: Cash Flow Statement (Fixed assets purchased FY26 = ₹72 Cr)
B15: Net Cash: Balance Sheet (Investments ₹2,949 Cr − Borrowings ₹5 Cr = ₹2,944 Cr net cash)
B16: Shares: Equity Capital ₹51 Cr ÷ Face Value ₹2 = 25.5 Cr shares
B17: Current Price: NSE closing price 16 Jun 2026 (₹2,885/share)
... B39: Based on publicly available financials from Screener.in and BSE/NSE filings. Projections are illustrative — assumptions are the author's and not a formal recommendation. Not investment advice. MCX is a real listed company; verify all figures before use.

Sheet Assumptions
A1: DCFdesk — Model Assumptions
A2: Multi Commodity Exchange of India Ltd (MCX) · NSE: MCX · ₹ Crores · FY26 TTM base
C3: Bear | D3: Base | E3: Bull | F3: Notes
A5: REVENUE ASSUMPTIONS
A6: Year 0 Revenue (₹ Cr) — FY26 TTM LTM | C6: 2302 | D6: 2302 | E6: 2302 | F6: Screener.in FY26 TTM · Revenue from operations
A7: Year 1 Revenue Growth | C7: 0.05 | D7: 0.12 | E7: 0.18 | F7: Bear: normalisation; Bull: commodity volume boom
A8: Year 2 Revenue Growth | C8: 0.05 | D8: 0.1 | E8: 0.16
A9: Year 3 Revenue Growth | C9: 0.04 | D9: 0.09 | E9: 0.14
A10: Year 4 Revenue Growth | C10: 0.04 | D10: 0.08 | E10: 0.12
A11: Year 5 Revenue Growth | C11: 0.03 | D11: 0.07 | E11: 0.1 | F11: 5yr CAGR: Bear ~4%, Base ~9%, Bull ~14%
A13: EBITDA MARGIN ASSUMPTIONS
A14: Year 0 EBITDA Margin % — FY26 TTM | C14: 0.747 | D14: 0.747 | E14: 0.747 | F14: Op Profit ₹1,642 + D&A ₹78 = EBITDA ₹1,720 ÷ Revenue ₹2,302 = 74.7%
A15: Year 1 EBITDA Margin % | C15: 0.65 | D15: 0.68 | E15: 0.72
A16: Year 2 EBITDA Margin % | C16: 0.62 | D16: 0.67 | E16: 0.72
A17: Year 3 EBITDA Margin % | C17: 0.6 | D17: 0.67 | E17: 0.71
A18: Year 4 EBITDA Margin % | C18: 0.58 | D18: 0.66 | E18: 0.7
A19: Year 5 EBITDA Margin % | C19: 0.56 | D19: 0.65 | E19: 0.7 | F19: Bear: competition/costs compress margins to 56%. Bull: moat holds at 70%
A21: CAPITAL EXPENDITURE & D&A
A22: D&A (% of Revenue) | C22: 0.035 | D22: 0.035 | E22: 0.035 | F22: D&A ₹78 Cr ÷ Revenue ₹2,302 Cr = 3.4% FY26. Asset-light exchange.
A23: Capex (% of Revenue) | C23: 0.035 | D23: 0.035 | E23: 0.03 | F23: Fixed assets purchased ₹72 Cr FY26 (Cash Flow Statement). Tech refresh cycle.
A24: Δ NWC (% of Revenue Change) | C24: 0.01 | D24: 0.01 | E24: 0.01 | F24: Minimal true NWC for exchange. Margin money is settlement obligation, not traditional NWC.
A26: TAX, CAPITAL STRUCTURE & MARKET DATA
A27: Effective Tax Rate | C27: 0.21 | D27: 0.21 | E27: 0.21 | F27: FY26 effective rate 21% (P&L). Same across scenarios.
A28: Net Cash (₹ Cr) — ADD to EV to get Equity Value | C28: 2944 | D28: 2944 | E28: 2944 | F28: Investments ₹2,949 Cr − Borrowings ₹5 Cr = ₹2,944 Cr NET CASH. MCX has NO net debt.
A29: Shares Outstanding (Cr) | C29: 25.5 | D29: 25.5 | E29: 25.5 | F29: Equity Capital ₹51 Cr ÷ Face Value ₹2 = 25.5 Cr shares
A30: Current Share Price (₹/share) | C30: 2885 | D30: 2885 | E30: 2885 | F30: NSE closing price 16 Jun 2026
A32: WACC INPUTS (CAPM)
A33: Risk-Free Rate (India 10Y G-Sec) | C33: 0.0685 | D33: 0.0685 | E33: 0.0685 | F33: Illustrative 10Y G-Sec rate ~6.85%
A34: Market Risk Premium (India Equity) | C34: 0.065 | D34: 0.06 | E34: 0.055 | F34: Bear: 6.5% (higher risk demanded). Bull: 5.5% (moat reassurance)
A35: Levered Beta | C35: 1.2 | D35: 1.05 | E35: 0.9 | F35: Bear 1.20 (regulatory/volume risk). Base 1.05. Bull 0.90 (monopoly stability)
A36: Cost of Debt (Pre-Tax) | C36: 0.095 | D36: 0.09 | E36: 0.085 | F36: MCX has minimal debt. Illustrative only.
A37: Debt / (Debt+Equity) at Market | C37: 0.01 | D37: 0.01 | E37: 0.01 | F37: MCX is essentially un-levered. 1% debt weight illustrative.
A39: TERMINAL VALUE ASSUMPTIONS
A40: Terminal Growth Rate (g) | C40: 0.04 | D40: 0.05 | E40: 0.055 | F40: Bear 4% (GDP+inflation floor). Base 5%. Bull 5.5% (commodity volumes structurally growing).
A41: Exit EBITDA Multiple (alt. TV method) | C41: 30 | D41: 35 | E41: 40 | F41: Exchange monopoly comps: BSE ~35x, global exchanges 25-45x EBITDA. Bear 30x. Base 35x. Bull 40x.
A43: SCENARIO DESCRIPTIONS
A44: Bear Case: | C44: Volume normalisation, margin compression, higher risk premium
A45: Base Case: | C45: Steady ADTV growth, margins normalise to 65%, new options products
A46: Bull Case: | C46: Commodity super-cycle, new index futures, retail trading boom

Sheet Income Stmt
A1: Income Statement — 3 Scenarios
A2: ₹ Crores · Year 0 = FY26 LTM base · EBIT = EBITDA − D&A (MCX has zero interest expense)
A4: ── Bear Case ── | Volume normalisation, margin compression, higher risk premium
B5: Y0 (LTM FY26) | C5: Y1 | D5: Y2 | E5: Y3 | F5: Y4 | G5: Y5
A6: Revenue | B6: =Assumptions!$C$6 -> 2302 | C6: =B6*(1+Assumptions!$C$7) -> 2417.1 | D6: =C6*(1+Assumptions!$C$8) -> 2537.955 | E6: =D6*(1+Assumptions!$C$9) -> 2639.4732 | F6: =E6*(1+Assumptions!$C$10) -> 2745.0521 | G6: =F6*(1+Assumptions!$C$11) -> 2827.4037
A7: EBITDA Margin % | B7: =Assumptions!$C$14 -> 0.747 | C7: =Assumptions!$C$15 -> 0.65 | D7: =Assumptions!$C$16 -> 0.62 | E7: =Assumptions!$C$17 -> 0.6 | F7: =Assumptions!$C$18 -> 0.58 | G7: =Assumptions!$C$19 -> 0.56
A8: EBITDA | B8: =B6*B7 -> 1719.594 | C8: =C6*C7 -> 1571.115 | D8: =D6*D7 -> 1573.5321 | E8: =E6*E7 -> 1583.6839 | F8: =F6*F7 -> 1592.1302 | G8: =G6*G7 -> 1583.3461
A9: D&A | B9: =Assumptions!$C$22*B6 -> 80.57 | C9: =Assumptions!$C$22*C6 -> 84.5985 | D9: =Assumptions!$C$22*D6 -> 88.828425 | E9: =Assumptions!$C$22*E6 -> 92.381562 | F9: =Assumptions!$C$22*F6 -> 96.076824 | G9: =Assumptions!$C$22*G6 -> 98.959129
A10: EBIT (= EBITDA − D&A; interest = 0 for MCX) | B10: =B8-B9 -> 1639.024 | C10: =C8-C9 -> 1486.5165 | D10: =D8-D9 -> 1484.7037 | E10: =E8-E9 -> 1491.3024 | F10: =F8-F9 -> 1496.0534 | G10: =G8-G9 -> 1484.3869
A11: Capex | B11: =Assumptions!$C$23*B6 -> 80.57 | C11: =Assumptions!$C$23*C6 -> 84.5985 | D11: =Assumptions!$C$23*D6 -> 88.828425 | E11: =Assumptions!$C$23*E6 -> 92.381562 | F11: =Assumptions!$C$23*F6 -> 96.076824 | G11: =Assumptions!$C$23*G6 -> 98.959129
A12: Δ NWC (NWC % × Revenue Change) | B12: 0 | C12: =(C6-B6)*Assumptions!$C$24 -> 1.151 | D12: =(D6-C6)*Assumptions!$C$24 -> 1.20855 | E12: =(E6-D6)*Assumptions!$C$24 -> 1.015182 | F12: =(F6-E6)*Assumptions!$C$24 -> 1.0557893 | G12: =(G6-F6)*Assumptions!$C$24 -> 0.82351564
A19: ── Base Case ── | Steady ADTV growth, margins normalise to 65%, new options products
B20: Y0 (LTM FY26) | C20: Y1 | D20: Y2 | E20: Y3 | F20: Y4 | G20: Y5
A21: Revenue | B21: =Assumptions!$C$6 -> 2302 | C21: =B21*(1+Assumptions!$D$7) -> 2578.24 | D21: =C21*(1+Assumptions!$D$8) -> 2836.064 | E21: =D21*(1+Assumptions!$D$9) -> 3091.3098 | F21: =E21*(1+Assumptions!$D$10) -> 3338.6145 | G21: =F21*(1+Assumptions!$D$11) -> 3572.3176
A22: EBITDA Margin % | B22: =Assumptions!$C$14 -> 0.747 | C22: =Assumptions!$D$15 -> 0.68 | D22: =Assumptions!$D$16 -> 0.67 | E22: =Assumptions!$D$17 -> 0.67 | F22: =Assumptions!$D$18 -> 0.66 | G22: =Assumptions!$D$19 -> 0.65
A23: EBITDA | B23: =B21*B22 -> 1719.594 | C23: =C21*C22 -> 1753.2032 | D23: =D21*D22 -> 1900.1629 | E23: =E21*E22 -> 2071.1775 | F23: =F21*F22 -> 2203.4856 | G23: =G21*G22 -> 2322.0064
A24: D&A | B24: =Assumptions!$D$22*B21 -> 80.57 | C24: =Assumptions!$D$22*C21 -> 90.2384 | D24: =Assumptions!$D$22*D21 -> 99.26224 | E24: =Assumptions!$D$22*E21 -> 108.19584 | F24: =Assumptions!$D$22*F21 -> 116.85151 | G24: =Assumptions!$D$22*G21 -> 125.03111
A25: EBIT (= EBITDA − D&A; interest = 0 for MCX) | B25: =B23-B24 -> 1639.024 | C25: =C23-C24 -> 1662.9648 | D25: =D23-D24 -> 1800.9006 | E25: =E23-E24 -> 1962.9817 | F25: =F23-F24 -> 2086.6341 | G25: =G23-G24 -> 2196.9753
A26: Capex | B26: =Assumptions!$D$23*B21 -> 80.57 | C26: =Assumptions!$D$23*C21 -> 90.2384 | D26: =Assumptions!$D$23*D21 -> 99.26224 | E26: =Assumptions!$D$23*E21 -> 108.19584 | F26: =Assumptions!$D$23*F21 -> 116.85151 | G26: =Assumptions!$D$23*G21 -> 125.03111
A27: Δ NWC (NWC % × Revenue Change) | B27: 0 | C27: =(C21-B21)*Assumptions!$D$24 -> 2.7624 | D27: =(D21-C21)*Assumptions!$D$24 -> 2.57824 | E27: =(E21-D21)*Assumptions!$D$24 -> 2.5524576 | F27: =(F21-E21)*Assumptions!$D$24 -> 2.4730478 | G27: =(G21-F21)*Assumptions!$D$24 -> 2.3370302
A34: ── Bull Case ── | Commodity super-cycle, new index futures, retail trading boom
B35: Y0 (LTM FY26) | C35: Y1 | D35: Y2 | E35: Y3 | F35: Y4 | G35: Y5
A36: Revenue | B36: =Assumptions!$C$6 -> 2302 | C36: =B36*(1+Assumptions!$E$7) -> 2716.36 | D36: =C36*(1+Assumptions!$E$8) -> 3150.9776 | E36: =D36*(1+Assumptions!$E$9) -> 3592.1145 | F36: =E36*(1+Assumptions!$E$10) -> 4023.1682 | G36: =F36*(1+Assumptions!$E$11) -> 4425.485
A37: EBITDA Margin % | B37: =Assumptions!$C$14 -> 0.747 | C37: =Assumptions!$E$15 -> 0.72 | D37: =Assumptions!$E$16 -> 0.72 | E37: =Assumptions!$E$17 -> 0.71 | F37: =Assumptions!$E$18 -> 0.7 | G37: =Assumptions!$E$19 -> 0.7
A38: EBITDA | B38: =B36*B37 -> 1719.594 | C38: =C36*C37 -> 1955.7792 | D38: =D36*D37 -> 2268.7039 | E38: =E36*E37 -> 2550.4013 | F38: =F36*F37 -> 2816.2177 | G38: =G36*G37 -> 3097.8395
A39: D&A | B39: =Assumptions!$E$22*B36 -> 80.57 | C39: =Assumptions!$E$22*C36 -> 95.0726 | D39: =Assumptions!$E$22*D36 -> 110.28422 | E39: =Assumptions!$E$22*E36 -> 125.72401 | F39: =Assumptions!$E$22*F36 -> 140.81089 | G39: =Assumptions!$E$22*G36 -> 154.89198
A40: EBIT (= EBITDA − D&A; interest = 0 for MCX) | B40: =B38-B39 -> 1639.024 | C40: =C38-C39 -> 1860.7066 | D40: =D38-D39 -> 2158.4197 | E40: =E38-E39 -> 2424.6773 | F40: =F38-F39 -> 2675.4069 | G40: =G38-G39 -> 2942.9475
A41: Capex | B41: =Assumptions!$E$23*B36 -> 69.06 | C41: =Assumptions!$E$23*C36 -> 81.4908 | D41: =Assumptions!$E$23*D36 -> 94.529328 | E41: =Assumptions!$E$23*E36 -> 107.76343 | F41: =Assumptions!$E$23*F36 -> 120.69505 | G41: =Assumptions!$E$23*G36 -> 132.76455
A42: Δ NWC (NWC % × Revenue Change) | B42: 0 | C42: =(C36-B36)*Assumptions!$E$24 -> 4.1436 | D42: =(D36-C36)*Assumptions!$E$24 -> 4.346176 | E42: =(E36-D36)*Assumptions!$E$24 -> 4.4113686 | F42: =(F36-E36)*Assumptions!$E$24 -> 4.3105374 | G42: =(G36-F36)*Assumptions!$E$24 -> 4.0231682

Sheet FCFF Build
A1: Free Cash Flow to Firm (FCFF) — 3 Scenarios
A2: ₹ Crores · FCFF = EBIT×(1-Tax) + D&A − Capex − ΔNWC
A4: ── Bear Case ──
B5: Y0 (LTM) | C5: Y1 | D5: Y2 | E5: Y3 | F5: Y4 | G5: Y5
A6: EBIT (from Income Stmt) | B6: ='Income Stmt'!B10 -> 1639.024 | C6: ='Income Stmt'!C10 -> 1486.5165 | D6: ='Income Stmt'!D10 -> 1484.7037 | E6: ='Income Stmt'!E10 -> 1491.3024 | F6: ='Income Stmt'!F10 -> 1496.0534 | G6: ='Income Stmt'!G10 -> 1484.3869
A7: Tax Rate | B7: =Assumptions!$C$27 -> 0.21 | C7: =Assumptions!$C$27 -> 0.21 | D7: =Assumptions!$C$27 -> 0.21 | E7: =Assumptions!$C$27 -> 0.21 | F7: =Assumptions!$C$27 -> 0.21 | G7: =Assumptions!$C$27 -> 0.21
A8: NOPAT = EBIT × (1 − Tax) | B8: =B6*(1-B7) -> 1294.829 | C8: =C6*(1-C7) -> 1174.348 | D8: =D6*(1-D7) -> 1172.9159 | E8: =E6*(1-E7) -> 1178.1289 | F8: =F6*(1-F7) -> 1181.8822 | G8: =G6*(1-G7) -> 1172.6657
A9: Add: D&A | B9: ='Income Stmt'!B9 -> 80.57 | C9: ='Income Stmt'!C9 -> 84.5985 | D9: ='Income Stmt'!D9 -> 88.828425 | E9: ='Income Stmt'!E9 -> 92.381562 | F9: ='Income Stmt'!F9 -> 96.076824 | G9: ='Income Stmt'!G9 -> 98.959129
A10: Less: Capex | B10: ='Income Stmt'!B11 -> 80.57 | C10: ='Income Stmt'!C11 -> 84.5985 | D10: ='Income Stmt'!D11 -> 88.828425 | E10: ='Income Stmt'!E11 -> 92.381562 | F10: ='Income Stmt'!F11 -> 96.076824 | G10: ='Income Stmt'!G11 -> 98.959129
A11: Less: Δ NWC | B11: ='Income Stmt'!B12 -> 0 | C11: ='Income Stmt'!C12 -> 1.151 | D11: ='Income Stmt'!D12 -> 1.20855 | E11: ='Income Stmt'!E12 -> 1.015182 | F11: ='Income Stmt'!F12 -> 1.0557893 | G11: ='Income Stmt'!G12 -> 0.82351564
A12: FCFF | B12: =B8+B9-B10-B11 -> 1294.829 | C12: =C8+C9-C10-C11 -> 1173.197 | D12: =D8+D9-D10-D11 -> 1171.7074 | E12: =E8+E9-E10-E11 -> 1177.1137 | F12: =F8+F9-F10-F11 -> 1180.8264 | G12: =G8+G9-G10-G11 -> 1171.8422
A17: ── Base Case ──
B18: Y0 (LTM) | C18: Y1 | D18: Y2 | E18: Y3 | F18: Y4 | G18: Y5
A19: EBIT (from Income Stmt) | B19: ='Income Stmt'!B25 -> 1639.024 | C19: ='Income Stmt'!C25 -> 1662.9648 | D19: ='Income Stmt'!D25 -> 1800.9006 | E19: ='Income Stmt'!E25 -> 1962.9817 | F19: ='Income Stmt'!F25 -> 2086.6341 | G19: ='Income Stmt'!G25 -> 2196.9753
A20: Tax Rate | B20: =Assumptions!$D$27 -> 0.21 | C20: =Assumptions!$D$27 -> 0.21 | D20: =Assumptions!$D$27 -> 0.21 | E20: =Assumptions!$D$27 -> 0.21 | F20: =Assumptions!$D$27 -> 0.21 | G20: =Assumptions!$D$27 -> 0.21
A21: NOPAT = EBIT × (1 − Tax) | B21: =B19*(1-B20) -> 1294.829 | C21: =C19*(1-C20) -> 1313.7422 | D21: =D19*(1-D20) -> 1422.7115 | E21: =E19*(1-E20) -> 1550.7555 | F21: =F19*(1-F20) -> 1648.4409 | G21: =G19*(1-G20) -> 1735.6105
A22: Add: D&A | B22: ='Income Stmt'!B24 -> 80.57 | C22: ='Income Stmt'!C24 -> 90.2384 | D22: ='Income Stmt'!D24 -> 99.26224 | E22: ='Income Stmt'!E24 -> 108.19584 | F22: ='Income Stmt'!F24 -> 116.85151 | G22: ='Income Stmt'!G24 -> 125.03111
A23: Less: Capex | B23: ='Income Stmt'!B26 -> 80.57 | C23: ='Income Stmt'!C26 -> 90.2384 | D23: ='Income Stmt'!D26 -> 99.26224 | E23: ='Income Stmt'!E26 -> 108.19584 | F23: ='Income Stmt'!F26 -> 116.85151 | G23: ='Income Stmt'!G26 -> 125.03111
A24: Less: Δ NWC | B24: ='Income Stmt'!B27 -> 0 | C24: ='Income Stmt'!C27 -> 2.7624 | D24: ='Income Stmt'!D27 -> 2.57824 | E24: ='Income Stmt'!E27 -> 2.5524576 | F24: ='Income Stmt'!F27 -> 2.4730478 | G24: ='Income Stmt'!G27 -> 2.3370302
A25: FCFF | B25: =B21+B22-B23-B24 -> 1294.829 | C25: =C21+C22-C23-C24 -> 1310.9798 | D25: =D21+D22-D23-D24 -> 1420.1333 | E25: =E21+E22-E23-E24 -> 1548.2031 | F25: =F21+F22-F23-F24 -> 1645.9679 | G25: =G21+G22-G23-G24 -> 1733.2735
A30: ── Bull Case ──
B31: Y0 (LTM) | C31: Y1 | D31: Y2 | E31: Y3 | F31: Y4 | G31: Y5
A32: EBIT (from Income Stmt) | B32: ='Income Stmt'!B40 -> 1639.024 | C32: ='Income Stmt'!C40 -> 1860.7066 | D32: ='Income Stmt'!D40 -> 2158.4197 | E32: ='Income Stmt'!E40 -> 2424.6773 | F32: ='Income Stmt'!F40 -> 2675.4069 | G32: ='Income Stmt'!G40 -> 2942.9475
A33: Tax Rate | B33: =Assumptions!$E$27 -> 0.21 | C33: =Assumptions!$E$27 -> 0.21 | D33: =Assumptions!$E$27 -> 0.21 | E33: =Assumptions!$E$27 -> 0.21 | F33: =Assumptions!$E$27 -> 0.21 | G33: =Assumptions!$E$27 -> 0.21
A34: NOPAT = EBIT × (1 − Tax) | B34: =B32*(1-B33) -> 1294.829 | C34: =C32*(1-C33) -> 1469.9582 | D34: =D32*(1-D33) -> 1705.1515 | E34: =E32*(1-E33) -> 1915.495 | F34: =F32*(1-F33) -> 2113.5714 | G34: =G32*(1-G33) -> 2324.9286
A35: Add: D&A | B35: ='Income Stmt'!B39 -> 80.57 | C35: ='Income Stmt'!C39 -> 95.0726 | D35: ='Income Stmt'!D39 -> 110.28422 | E35: ='Income Stmt'!E39 -> 125.72401 | F35: ='Income Stmt'!F39 -> 140.81089 | G35: ='Income Stmt'!G39 -> 154.89198
A36: Less: Capex | B36: ='Income Stmt'!B41 -> 69.06 | C36: ='Income Stmt'!C41 -> 81.4908 | D36: ='Income Stmt'!D41 -> 94.529328 | E36: ='Income Stmt'!E41 -> 107.76343 | F36: ='Income Stmt'!F41 -> 120.69505 | G36: ='Income Stmt'!G41 -> 132.76455
A37: Less: Δ NWC | B37: ='Income Stmt'!B42 -> 0 | C37: ='Income Stmt'!C42 -> 4.1436 | D37: ='Income Stmt'!D42 -> 4.346176 | E37: ='Income Stmt'!E42 -> 4.4113686 | F37: ='Income Stmt'!F42 -> 4.3105374 | G37: ='Income Stmt'!G42 -> 4.0231682
A38: FCFF | B38: =B34+B35-B36-B37 -> 1306.339 | C38: =C34+C35-C36-C37 -> 1479.3964 | D38: =D34+D35-D36-D37 -> 1716.5602 | E38: =E34+E35-E36-E37 -> 1929.0442 | F38: =F34+F35-F36-F37 -> 2129.3767 | G38: =G34+G35-G36-G37 -> 2343.0328

Sheet WACC
A1: WACC — 3 Scenarios
A2: CAPM-based Cost of Equity + Blended Cost of Debt (MCX is near un-levered)
C3: Bear | D3: Base | E3: Bull
A5: COST OF EQUITY (CAPM)
A6: Risk-Free Rate | C6: =Assumptions!C33 -> 0.0685 | D6: =Assumptions!D33 -> 0.0685 | E6: =Assumptions!E33 -> 0.0685
A7: Market Risk Premium | C7: =Assumptions!C34 -> 0.065 | D7: =Assumptions!D34 -> 0.06 | E7: =Assumptions!E34 -> 0.055
A8: Levered Beta | C8: =Assumptions!C35 -> 1.2 | D8: =Assumptions!D35 -> 1.05 | E8: =Assumptions!E35 -> 0.9
A9: Cost of Equity = Rf+β×MRP | C9: =C6+C8*C7 -> 0.1465 | D9: =D6+D8*D7 -> 0.1315 | E9: =E6+E8*E7 -> 0.118
A11: COST OF DEBT
A12: Cost of Debt (Pre-Tax) | C12: =Assumptions!C36 -> 0.095 | D12: =Assumptions!D36 -> 0.09 | E12: =Assumptions!E36 -> 0.085
A13: Tax Rate | C13: =Assumptions!C27 -> 0.21 | D13: =Assumptions!D27 -> 0.21 | E13: =Assumptions!E27 -> 0.21
A14: Cost of Debt (Post-Tax) | C14: =C12*(1-C13) -> 0.07505 | D14: =D12*(1-D13) -> 0.0711 | E14: =E12*(1-E13) -> 0.06715
A16: CAPITAL WEIGHTS
A17: Debt / (Debt+Equity) | C17: =Assumptions!C37 -> 0.01 | D17: =Assumptions!D37 -> 0.01 | E17: =Assumptions!E37 -> 0.01
A18: Equity / (Debt+Equity) | C18: =1-C17 -> 0.99 | D18: =1-D17 -> 0.99 | E18: =1-E17 -> 0.99
A20: WACC
A21: WACC = We×CoE + Wd×CoD | C21: =C18*C9+C17*C14 -> 0.1457855 | D21: =D18*D9+D17*D14 -> 0.130896 | E21: =E18*E9+E17*E14 -> 0.1174915

Sheet DCF Valuation
A1: DCF Valuation — 3 Scenarios
A2: ₹ Crores · FCFFs from FCFF Build · WACC from WACC sheet · MCX has net cash → ADD to EV
C3: Bear | D3: Base | E3: Bull | G3: Notes
A5: DISCOUNT RATE
A6: WACC | C6: =WACC!C21 -> 0.1457855 | D6: =WACC!D21 -> 0.130896 | E6: =WACC!E21 -> 0.1174915
A8: PV OF FREE CASH FLOWS (Y1–Y5)
A9: PV of FCFF (Years 1–5) | C9: =NPV(C6,'FCFF Build'!C12,'FCFF Build'!D12,'FCFF Build'!E12,'FCFF Build'!F12,'FCFF Build'!G12) -> 3977.5125 | D9: =NPV(D6,'FCFF Build'!C25,'FCFF Build'!D25,'FCFF Build'!E25,'FCFF Build'!F25,'FCFF Build'!G25) -> 5283.423 | E9: =NPV(E6,'FCFF Build'!C38,'FCFF Build'!D38,'FCFF Build'!E38,'FCFF Build'!F38,'FCFF Build'!G38) -> 6790.6977 | G9: Excel NPV() discounts Y1-Y5 FCFFs at WACC
A11: TERMINAL VALUE — METHOD 1: PERPETUITY GROWTH (GORDON GROWTH)
A12: Year 5 FCFF | C12: ='FCFF Build'!G12 -> 1171.8422 | D12: ='FCFF Build'!G25 -> 1733.2735 | E12: ='FCFF Build'!G38 -> 2343.0328 | G12: Year 5 FCFF from FCFF Build tab
A13: Terminal Growth Rate (g) | C13: =Assumptions!C40 -> 0.04 | D13: =Assumptions!D40 -> 0.05 | E13: =Assumptions!E40 -> 0.055 | G13: From Assumptions tab
A14: Terminal FCFF = Y5_FCFF × (1+g) | C14: =C12*(1+C13) -> 1218.7159 | D14: =D12*(1+D13) -> 1819.9371 | E14: =E12*(1+E13) -> 2471.8996
A15: Terminal Value = Terminal FCFF / (WACC − g) | C15: =C14/(C6-C13) -> 11520.632 | D15: =D14/(D6-D13) -> 22497.245 | E15: =E14/(E6-E13) -> 39555.773 | G15: Gordon Growth Model
A16: PV of Terminal Value | C16: =C15/(1+C6)^5 -> 5833.9098 | D16: =D15/(1+D6)^5 -> 12162.308 | E16: =E15/(1+E6)^5 -> 22698.06 | G16: Discounted at WACC^5
A17: Implied EV (Perpetuity Method) | C17: =C9+C16 -> 9811.4222 | D17: =D9+D16 -> 17445.731 | E17: =E9+E16 -> 29488.758 | G17: PV FCFFs + PV Terminal Value
A19: TERMINAL VALUE — METHOD 2: EXIT EBITDA MULTIPLE
A20: Year 5 EBITDA | C20: ='Income Stmt'!G8 -> 1583.3461 | D20: ='Income Stmt'!G23 -> 2322.0064 | E20: ='Income Stmt'!G38 -> 3097.8395
A21: Exit EBITDA Multiple | C21: =Assumptions!C41 -> 30 | D21: =Assumptions!D41 -> 35 | E21: =Assumptions!E41 -> 40
A22: Terminal Value | C22: =C20*C21 -> 47500.382 | D22: =D20*D21 -> 81270.224 | E22: =E20*E21 -> 123913.58
A23: PV of Terminal Value | C23: =C22/(1+C6)^5 -> 24053.623 | D23: =D22/(1+D6)^5 -> 43935.758 | E23: =E22/(1+E6)^5 -> 71104.611
A24: Implied EV (Exit Multiple Method) | C24: =C9+C23 -> 28031.135 | D24: =D9+D23 -> 49219.181 | E24: =E9+E23 -> 77895.309
A26: IMPLIED SHARE PRICE — BRIDGE: EV + NET CASH = EQUITY | MCX has net cash — adds to equity value
A27: Average Implied EV (2 methods) | C27: =AVERAGE(C17,C24) -> 18921.279 | D27: =AVERAGE(D17,D24) -> 33332.456 | E27: =AVERAGE(E17,E24) -> 53692.033
A28: Add: Net Cash (positive = MCX has cash, no debt) | C28: =Assumptions!C28 -> 2944 | D28: =Assumptions!D28 -> 2944 | E28: =Assumptions!E28 -> 2944
A29: Implied Equity Value (= EV + Net Cash) | C29: =C27+C28 -> 21865.279 | D29: =D27+D28 -> 36276.456 | E29: =E27+E28 -> 56636.033
A30: Shares Outstanding (Cr) | C30: =Assumptions!C29 -> 25.5 | D30: =Assumptions!D29 -> 25.5 | E30: =Assumptions!E29 -> 25.5
A31: Implied Share Price (₹) | C31: =C29/C30 -> 857.46191 | D31: =D29/D30 -> 1422.6061 | E31: =E29/E30 -> 2221.0209
A32: Current Share Price (₹) | C32: =Assumptions!C30 -> 2885 | D32: =Assumptions!D30 -> 2885 | E32: =Assumptions!E30 -> 2885
A33: Upside / (Downside) to ₹2,885 | C33: =C31/C32-1 -> -0.70278617 | D33: =D31/D32-1 -> -0.50689563 | E33: =E31/E32-1 -> -0.23014873

Sheet Sensitivity
A1: Sensitivity Analysis — Base Case FCFFs
A2: Implied Share Price (₹) · WACC (rows) × variable (cols) · vs Current ₹2,885
A4: GRID 1 — WACC × TERMINAL GROWTH RATE → IMPLIED SHARE PRICE (Perpetuity Method)
A5: WACC ↓ / g → | B5: 0.025 | C5: 0.03 | D5: 0.035 | E5: 0.04 | F5: 0.045 | G5: 0.05 | H5: 0.055
A6: 0.085 | B6: =(NPV($A6,'FCFF Build'!C25,'FCFF Build'!D25,'FCFF Build'!E25,'FCFF Build'!F25,'FCFF Build'!G25)+('FCFF Build'!G25*(1+B5)/($A6-B5))/(1+$A6)^5+Assumptions!D28)/Assumptions!D29 -> 1121.6927 | C6: =(NPV($A6,'FCFF Build'!C25,'FCFF Build'!D25,'FCFF Build'!E25,'FCFF Build'!F25,'FCFF Build'!G25)+('FCFF Build'!G25*(1+C5)/($A6-C5))/(1+$A6)^5+Assumptions!D28)/Assumptions!D29 -> 1196.0056 | D6: =(NPV($A6,'FCFF Build'!C25,'FCFF Build'!D25,'FCFF Build'!E25,'FCFF Build'!F25,'FCFF Build'!G25)+('FCFF Build'!G25*(1+D5)/($A6-D5))/(1+$A6)^5+Assumptions!D28)/Assumptions!D29 -> 1285.181 | E6: =(NPV($A6,'FCFF Build'!C25,'FCFF Build'!D25,'FCFF Build'!E25,'FCFF Build'!F25,'FCFF Build'!G25)+('FCFF Build'!G25*(1+E5)/($A6-E5))/(1+$A6)^5+Assumptions!D28)/Assumptions!D29 -> 1394.1732 | F6: =(NPV($A6,'FCFF Build'!C25,'FCFF Build'!D25,'FCFF Build'!E25,'FCFF Build'!F25,'FCFF Build'!G25)+('FCFF Build'!G25*(1+F5)/($A6-F5))/(1+$A6)^5+Assumptions!D28)/Assumptions!D29 -> 1530.4135 | G6: =(NPV($A6,'FCFF Build'!C25,'FCFF Build'!D25,'FCFF Build'!E25,'FCFF Build'!F25,'FCFF Build'!G25)+('FCFF Build'!G25*(1+G5)/($A6-G5))/(1+$A6)^5+Assumptions!D28)/Assumptions!D29 -> 1705.5795 | H6: =(NPV($A6,'FCFF Build'!C25,'FCFF Build'!D25,'FCFF Build'!E25,'FCFF Build'!F25,'FCFF Build'!G25)+('FCFF Build'!G25*(1+H5)/($A6-H5))/(1+$A6)^5+Assumptions!D28)/Assumptions!D29 -> 1939.1342
A7: 0.09 | B7: =(NPV($A7,'FCFF Build'!C25,'FCFF Build'!D25,'FCFF Build'!E25,'FCFF Build'!F25,'FCFF Build'!G25)+('FCFF Build'!G25*(1+B5)/($A7-B5))/(1+$A7)^5+Assumptions!D28)/Assumptions!D29 -> 1042.9122 | C7: =(NPV($A7,'FCFF Build'!C25,'FCFF Build'!D25,'FCFF Build'!E25,'FCFF Build'!F25,'FCFF Build'!G25)+('FCFF Build'!G25*(1+C5)/($A7-C5))/(1+$A7)^5+Assumptions!D28)/Assumptions!D29 -> 1104.6464 | D7: =(NPV($A7,'FCFF Build'!C25,'FCFF Build'!D25,'FCFF Build'!E25,'FCFF Build'!F25,'FCFF Build'!G25)+('FCFF Build'!G25*(1+D5)/($A7-D5))/(1+$A7)^5+Assumptions!D28)/Assumptions!D29 -> 1177.6051 | E7: =(NPV($A7,'FCFF Build'!C25,'FCFF Build'!D25,'FCFF Build'!E25,'FCFF Build'!F25,'FCFF Build'!G25)+('FCFF Build'!G25*(1+E5)/($A7-E5))/(1+$A7)^5+Assumptions!D28)/Assumptions!D29 -> 1265.1555 | F7: =(NPV($A7,'FCFF Build'!C25,'FCFF Build'!D25,'FCFF Build'!E25,'FCFF Build'!F25,'FCFF Build'!G25)+('FCFF Build'!G25*(1+F5)/($A7-F5))/(1+$A7)^5+Assumptions!D28)/Assumptions!D29 -> 1372.1616 | G7: =(NPV($A7,'FCFF Build'!C25,'FCFF Build'!D25,'FCFF Build'!E25,'FCFF Build'!F25,'FCFF Build'!G25)+('FCFF Build'!G25*(1+G5)/($A7-G5))/(1+$A7)^5+Assumptions!D28)/Assumptions!D29 -> 1505.9192 | H7: =(NPV($A7,'FCFF Build'!C25,'FCFF Build'!D25,'FCFF Build'!E25,'FCFF Build'!F25,'FCFF Build'!G25)+('FCFF Build'!G25*(1+H5)/($A7-H5))/(1+$A7)^5+Assumptions!D28)/Assumptions!D29 -> 1677.8932
A8: 0.095 | B8: =(NPV($A8,'FCFF Build'!C25,'FCFF Build'!D25,'FCFF Build'!E25,'FCFF Build'!F25,'FCFF Build'!G25)+('FCFF Build'!G25*(1+B5)/($A8-B5))/(1+$A8)^5+Assumptions!D28)/Assumptions!D29 -> 975.40728 | C8: =(NPV($A8,'FCFF Build'!C25,'FCFF Build'!D25,'FCFF Build'!E25,'FCFF Build'!F25,'FCFF Build'!G25)+('FCFF Build'!G25*(1+C5)/($A8-C5))/(1+$A8)^5+Assumptions!D28)/Assumptions!D29 -> 1027.3625 | D8: =(NPV($A8,'FCFF Build'!C25,'FCFF Build'!D25,'FCFF Build'!E25,'FCFF Build'!F25,'FCFF Build'!G25)+('FCFF Build'!G25*(1+D5)/($A8-D5))/(1+$A8)^5+Assumptions!D28)/Assumptions!D29 -> 1087.9769 | E8: =(NPV($A8,'FCFF Build'!C25,'FCFF Build'!D25,'FCFF Build'!E25,'FCFF Build'!F25,'FCFF Build'!G25)+('FCFF Build'!G25*(1+E5)/($A8-E5))/(1+$A8)^5+Assumptions!D28)/Assumptions!D29 -> 1159.6121 | F8: =(NPV($A8,'FCFF Build'!C25,'FCFF Build'!D25,'FCFF Build'!E25,'FCFF Build'!F25,'FCFF Build'!G25)+('FCFF Build'!G25*(1+F5)/($A8-F5))/(1+$A8)^5+Assumptions!D28)/Assumptions!D29 -> 1245.5743 | G8: =(NPV($A8,'FCFF Build'!C25,'FCFF Build'!D25,'FCFF Build'!E25,'FCFF Build'!F25,'FCFF Build'!G25)+('FCFF Build'!G25*(1+G5)/($A8-G5))/(1+$A8)^5+Assumptions!D28)/Assumptions!D29 -> 1350.6393 | H8: =(NPV($A8,'FCFF Build'!C25,'FCFF Build'!D25,'FCFF Build'!E25,'FCFF Build'!F25,'FCFF Build'!G25)+('FCFF Build'!G25*(1+H5)/($A8-H5))/(1+$A8)^5+Assumptions!D28)/Assumptions!D29 -> 1481.9705
A9: 0.1 | B9: =(NPV($A9,'FCFF Build'!C25,'FCFF Build'!D25,'FCFF Build'!E25,'FCFF Build'!F25,'FCFF Build'!G25)+('FCFF Build'!G25*(1+B5)/($A9-B5))/(1+$A9)^5+Assumptions!D28)/Assumptions!D29 -> 916.92252 | C9: =(NPV($A9,'FCFF Build'!C25,'FCFF Build'!D25,'FCFF Build'!E25,'FCFF Build'!F25,'FCFF Build'!G25)+('FCFF Build'!G25*(1+C5)/($A9-C5))/(1+$A9)^5+Assumptions!D28)/Assumptions!D29 -> 961.13724 | D9: =(NPV($A9,'FCFF Build'!C25,'FCFF Build'!D25,'FCFF Build'!E25,'FCFF Build'!F25,'FCFF Build'!G25)+('FCFF Build'!G25*(1+D5)/($A9-D5))/(1+$A9)^5+Assumptions!D28)/Assumptions!D29 -> 1012.1542 | E9: =(NPV($A9,'FCFF Build'!C25,'FCFF Build'!D25,'FCFF Build'!E25,'FCFF Build'!F25,'FCFF Build'!G25)+('FCFF Build'!G25*(1+E5)/($A9-E5))/(1+$A9)^5+Assumptions!D28)/Assumptions!D29 -> 1071.674 | F9: =(NPV($A9,'FCFF Build'!C25,'FCFF Build'!D25,'FCFF Build'!E25,'FCFF Build'!F25,'FCFF Build'!G25)+('FCFF Build'!G25*(1+F5)/($A9-F5))/(1+$A9)^5+Assumptions!D28)/Assumptions!D29 -> 1142.0156 | G9: =(NPV($A9,'FCFF Build'!C25,'FCFF Build'!D25,'FCFF Build'!E25,'FCFF Build'!F25,'FCFF Build'!G25)+('FCFF Build'!G25*(1+G5)/($A9-G5))/(1+$A9)^5+Assumptions!D28)/Assumptions!D29 -> 1226.4256 | H9: =(NPV($A9,'FCFF Build'!C25,'FCFF Build'!D25,'FCFF Build'!E25,'FCFF Build'!F25,'FCFF Build'!G25)+('FCFF Build'!G25*(1+H5)/($A9-H5))/(1+$A9)^5+Assumptions!D28)/Assumptions!D29 -> 1329.5932
A10: 0.105 | B10: =(NPV($A10,'FCFF Build'!C25,'FCFF Build'!D25,'FCFF Build'!E25,'FCFF Build'!F25,'FCFF Build'!G25)+('FCFF Build'!G25*(1+B5)/($A10-B5))/(1+$A10)^5+Assumptions!D28)/Assumptions!D29 -> 865.76619 | C10: =(NPV($A10,'FCFF Build'!C25,'FCFF Build'!D25,'FCFF Build'!E25,'FCFF Build'!F25,'FCFF Build'!G25)+('FCFF Build'!G25*(1+C5)/($A10-C5))/(1+$A10)^5+Assumptions!D28)/Assumptions!D29 -> 903.75858 | D10: =(NPV($A10,'FCFF Build'!C25,'FCFF Build'!D25,'FCFF Build'!E25,'FCFF Build'!F25,'FCFF Build'!G25)+('FCFF Build'!G25*(1+D5)/($A10-D5))/(1+$A10)^5+Assumptions!D28)/Assumptions!D29 -> 947.17844 | E10: =(NPV($A10,'FCFF Build'!C25,'FCFF Build'!D25,'FCFF Build'!E25,'FCFF Build'!F25,'FCFF Build'!G25)+('FCFF Build'!G25*(1+E5)/($A10-E5))/(1+$A10)^5+Assumptions!D28)/Assumptions!D29 -> 997.27829 | F10: =(NPV($A10,'FCFF Build'!C25,'FCFF Build'!D25,'FCFF Build'!E25,'FCFF Build'!F25,'FCFF Build'!G25)+('FCFF Build'!G25*(1+F5)/($A10-F5))/(1+$A10)^5+Assumptions!D28)/Assumptions!D29 -> 1055.7281 | G10: =(NPV($A10,'FCFF Build'!C25,'FCFF Build'!D25,'FCFF Build'!E25,'FCFF Build'!F25,'FCFF Build'!G25)+('FCFF Build'!G25*(1+G5)/($A10-G5))/(1+$A10)^5+Assumptions!D28)/Assumptions!D29 -> 1124.8052 | H10: =(NPV($A10,'FCFF Build'!C25,'FCFF Build'!D25,'FCFF Build'!E25,'FCFF Build'!F25,'FCFF Build'!G25)+('FCFF Build'!G25*(1+H5)/($A10-H5))/(1+$A10)^5+Assumptions!D28)/Assumptions!D29 -> 1207.6976
A11: 0.11 | B11: =(NPV($A11,'FCFF Build'!C25,'FCFF Build'!D25,'FCFF Build'!E25,'FCFF Build'!F25,'FCFF Build'!G25)+('FCFF Build'!G25*(1+B5)/($A11-B5))/(1+$A11)^5+Assumptions!D28)/Assumptions!D29 -> 820.64467 | C11: =(NPV($A11,'FCFF Build'!C25,'FCFF Build'!D25,'FCFF Build'!E25,'FCFF Build'!F25,'FCFF Build'!G25)+('FCFF Build'!G25*(1+C5)/($A11-C5))/(1+$A11)^5+Assumptions!D28)/Assumptions!D29 -> 853.56741 | D11: =(NPV($A11,'FCFF Build'!C25,'FCFF Build'!D25,'FCFF Build'!E25,'FCFF Build'!F25,'FCFF Build'!G25)+('FCFF Build'!G25*(1+D5)/($A11-D5))/(1+$A11)^5+Assumptions!D28)/Assumptions!D29 -> 890.87986 | E11: =(NPV($A11,'FCFF Build'!C25,'FCFF Build'!D25,'FCFF Build'!E25,'FCFF Build'!F25,'FCFF Build'!G25)+('FCFF Build'!G25*(1+E5)/($A11-E5))/(1+$A11)^5+Assumptions!D28)/Assumptions!D29 -> 933.52266 | F11: =(NPV($A11,'FCFF Build'!C25,'FCFF Build'!D25,'FCFF Build'!E25,'FCFF Build'!F25,'FCFF Build'!G25)+('FCFF Build'!G25*(1+F5)/($A11-F5))/(1+$A11)^5+Assumptions!D28)/Assumptions!D29 -> 982.72589 | G11: =(NPV($A11,'FCFF Build'!C25,'FCFF Build'!D25,'FCFF Build'!E25,'FCFF Build'!F25,'FCFF Build'!G25)+('FCFF Build'!G25*(1+G5)/($A11-G5))/(1+$A11)^5+Assumptions!D28)/Assumptions!D29 -> 1040.1297 | H11: =(NPV($A11,'FCFF Build'!C25,'FCFF Build'!D25,'FCFF Build'!E25,'FCFF Build'!F25,'FCFF Build'!G25)+('FCFF Build'!G25*(1+H5)/($A11-H5))/(1+$A11)^5+Assumptions!D28)/Assumptions!D29 -> 1107.9705
A12: 0.115 | B12: =(NPV($A12,'FCFF Build'!C25,'FCFF Build'!D25,'FCFF Build'!E25,'FCFF Build'!F25,'FCFF Build'!G25)+('FCFF Build'!G25*(1+B5)/($A12-B5))/(1+$A12)^5+Assumptions!D28)/Assumptions!D29 -> 780.5518 | C12: =(NPV($A12,'FCFF Build'!C25,'FCFF Build'!D25,'FCFF Build'!E25,'FCFF Build'!F25,'FCFF Build'!G25)+('FCFF Build'!G25*(1+C5)/($A12-C5))/(1+$A12)^5+Assumptions!D28)/Assumptions!D29 -> 809.29506 | D12: =(NPV($A12,'FCFF Build'!C25,'FCFF Build'!D25,'FCFF Build'!E25,'FCFF Build'!F25,'FCFF Build'!G25)+('FCFF Build'!G25*(1+D5)/($A12-D5))/(1+$A12)^5+Assumptions!D28)/Assumptions!D29 -> 841.63123 | E12: =(NPV($A12,'FCFF Build'!C25,'FCFF Build'!D25,'FCFF Build'!E25,'FCFF Build'!F25,'FCFF Build'!G25)+('FCFF Build'!G25*(1+E5)/($A12-E5))/(1+$A12)^5+Assumptions!D28)/Assumptions!D29 -> 878.27888 | F12: =(NPV($A12,'FCFF Build'!C25,'FCFF Build'!D25,'FCFF Build'!E25,'FCFF Build'!F25,'FCFF Build'!G25)+('FCFF Build'!G25*(1+F5)/($A12-F5))/(1+$A12)^5+Assumptions!D28)/Assumptions!D29 -> 920.16192 | G12: =(NPV($A12,'FCFF Build'!C25,'FCFF Build'!D25,'FCFF Build'!E25,'FCFF Build'!F25,'FCFF Build'!G25)+('FCFF Build'!G25*(1+G5)/($A12-G5))/(1+$A12)^5+Assumptions!D28)/Assumptions!D29 -> 968.4885 | H12: =(NPV($A12,'FCFF Build'!C25,'FCFF Build'!D25,'FCFF Build'!E25,'FCFF Build'!F25,'FCFF Build'!G25)+('FCFF Build'!G25*(1+H5)/($A12-H5))/(1+$A12)^5+Assumptions!D28)/Assumptions!D29 -> 1024.8695
A14: Base case WACC (~13.1%) and base g (5.0%) in approximate range rows 7-8, col 7
A16: GRID 2 — WACC × EXIT EBITDA MULTIPLE → IMPLIED SHARE PRICE (Exit Multiple Method)
A17: WACC ↓ / EV/EBITDA → | B17: 25 | C17: 28 | D17: 30 | E17: 32 | F17: 35 | G17: 38 | H17: 40
A18: 0.085 | B18: =(NPV($A18,'FCFF Build'!C25,'FCFF Build'!D25,'FCFF Build'!E25,'FCFF Build'!F25,'FCFF Build'!G25)+'Income Stmt'!G23*B17/(1+$A18)^5+Assumptions!D28)/Assumptions!D29 -> 1863.4158 | C18: =(NPV($A18,'FCFF Build'!C25,'FCFF Build'!D25,'FCFF Build'!E25,'FCFF Build'!F25,'FCFF Build'!G25)+'Income Stmt'!G23*C17/(1+$A18)^5+Assumptions!D28)/Assumptions!D29 -> 2045.0911 | D18: =(NPV($A18,'FCFF Build'!C25,'FCFF Build'!D25,'FCFF Build'!E25,'FCFF Build'!F25,'FCFF Build'!G25)+'Income Stmt'!G23*D17/(1+$A18)^5+Assumptions!D28)/Assumptions!D29 -> 2166.2079 | E18: =(NPV($A18,'FCFF Build'!C25,'FCFF Build'!D25,'FCFF Build'!E25,'FCFF Build'!F25,'FCFF Build'!G25)+'Income Stmt'!G23*E17/(1+$A18)^5+Assumptions!D28)/Assumptions!D29 -> 2287.3248 | F18: =(NPV($A18,'FCFF Build'!C25,'FCFF Build'!D25,'FCFF Build'!E25,'FCFF Build'!F25,'FCFF Build'!G25)+'Income Stmt'!G23*F17/(1+$A18)^5+Assumptions!D28)/Assumptions!D29 -> 2469 | G18: =(NPV($A18,'FCFF Build'!C25,'FCFF Build'!D25,'FCFF Build'!E25,'FCFF Build'!F25,'FCFF Build'!G25)+'Income Stmt'!G23*G17/(1+$A18)^5+Assumptions!D28)/Assumptions!D29 -> 2650.6753 | H18: =(NPV($A18,'FCFF Build'!C25,'FCFF Build'!D25,'FCFF Build'!E25,'FCFF Build'!F25,'FCFF Build'!G25)+'Income Stmt'!G23*H17/(1+$A18)^5+Assumptions!D28)/Assumptions!D29 -> 2771.7922
A19: 0.09 | B19: =(NPV($A19,'FCFF Build'!C25,'FCFF Build'!D25,'FCFF Build'!E25,'FCFF Build'!F25,'FCFF Build'!G25)+'Income Stmt'!G23*B17/(1+$A19)^5+Assumptions!D28)/Assumptions!D29 -> 1825.8315 | C19: =(NPV($A19,'FCFF Build'!C25,'FCFF Build'!D25,'FCFF Build'!E25,'FCFF Build'!F25,'FCFF Build'!G25)+'Income Stmt'!G23*C17/(1+$A19)^5+Assumptions!D28)/Assumptions!D29 -> 2003.378 | D19: =(NPV($A19,'FCFF Build'!C25,'FCFF Build'!D25,'FCFF Build'!E25,'FCFF Build'!F25,'FCFF Build'!G25)+'Income Stmt'!G23*D17/(1+$A19)^5+Assumptions!D28)/Assumptions!D29 -> 2121.7423 | E19: =(NPV($A19,'FCFF Build'!C25,'FCFF Build'!D25,'FCFF Build'!E25,'FCFF Build'!F25,'FCFF Build'!G25)+'Income Stmt'!G23*E17/(1+$A19)^5+Assumptions!D28)/Assumptions!D29 -> 2240.1066 | F19: =(NPV($A19,'FCFF Build'!C25,'FCFF Build'!D25,'FCFF Build'!E25,'FCFF Build'!F25,'FCFF Build'!G25)+'Income Stmt'!G23*F17/(1+$A19)^5+Assumptions!D28)/Assumptions!D29 -> 2417.653 | G19: =(NPV($A19,'FCFF Build'!C25,'FCFF Build'!D25,'FCFF Build'!E25,'FCFF Build'!F25,'FCFF Build'!G25)+'Income Stmt'!G23*G17/(1+$A19)^5+Assumptions!D28)/Assumptions!D29 -> 2595.1995 | H19: =(NPV($A19,'FCFF Build'!C25,'FCFF Build'!D25,'FCFF Build'!E25,'FCFF Build'!F25,'FCFF Build'!G25)+'Income Stmt'!G23*H17/(1+$A19)^5+Assumptions!D28)/Assumptions!D29 -> 2713.5638
A20: 0.095 | B20: =(NPV($A20,'FCFF Build'!C25,'FCFF Build'!D25,'FCFF Build'!E25,'FCFF Build'!F25,'FCFF Build'!G25)+'Income Stmt'!G23*B17/(1+$A20)^5+Assumptions!D28)/Assumptions!D29 -> 1789.2481 | C20: =(NPV($A20,'FCFF Build'!C25,'FCFF Build'!D25,'FCFF Build'!E25,'FCFF Build'!F25,'FCFF Build'!G25)+'Income Stmt'!G23*C17/(1+$A20)^5+Assumptions!D28)/Assumptions!D29 -> 1962.7779 | D20: =(NPV($A20,'FCFF Build'!C25,'FCFF Build'!D25,'FCFF Build'!E25,'FCFF Build'!F25,'FCFF Build'!G25)+'Income Stmt'!G23*D17/(1+$A20)^5+Assumptions!D28)/Assumptions!D29 -> 2078.4644 | E20: =(NPV($A20,'FCFF Build'!C25,'FCFF Build'!D25,'FCFF Build'!E25,'FCFF Build'!F25,'FCFF Build'!G25)+'Income Stmt'!G23*E17/(1+$A20)^5+Assumptions!D28)/Assumptions!D29 -> 2194.1508 | F20: =(NPV($A20,'FCFF Build'!C25,'FCFF Build'!D25,'FCFF Build'!E25,'FCFF Build'!F25,'FCFF Build'!G25)+'Income Stmt'!G23*F17/(1+$A20)^5+Assumptions!D28)/Assumptions!D29 -> 2367.6806 | G20: =(NPV($A20,'FCFF Build'!C25,'FCFF Build'!D25,'FCFF Build'!E25,'FCFF Build'!F25,'FCFF Build'!G25)+'Income Stmt'!G23*G17/(1+$A20)^5+Assumptions!D28)/Assumptions!D29 -> 2541.2103 | H20: =(NPV($A20,'FCFF Build'!C25,'FCFF Build'!D25,'FCFF Build'!E25,'FCFF Build'!F25,'FCFF Build'!G25)+'Income Stmt'!G23*H17/(1+$A20)^5+Assumptions!D28)/Assumptions!D29 -> 2656.8968
A21: 0.1 | B21: =(NPV($A21,'FCFF Build'!C25,'FCFF Build'!D25,'FCFF Build'!E25,'FCFF Build'!F25,'FCFF Build'!G25)+'Income Stmt'!G23*B17/(1+$A21)^5+Assumptions!D28)/Assumptions!D29 -> 1753.6345 | C21: =(NPV($A21,'FCFF Build'!C25,'FCFF Build'!D25,'FCFF Build'!E25,'FCFF Build'!F25,'FCFF Build'!G25)+'Income Stmt'!G23*C17/(1+$A21)^5+Assumptions!D28)/Assumptions!D29 -> 1923.256 | D21: =(NPV($A21,'FCFF Build'!C25,'FCFF Build'!D25,'FCFF Build'!E25,'FCFF Build'!F25,'FCFF Build'!G25)+'Income Stmt'!G23*D17/(1+$A21)^5+Assumptions!D28)/Assumptions!D29 -> 2036.3371 | E21: =(NPV($A21,'FCFF Build'!C25,'FCFF Build'!D25,'FCFF Build'!E25,'FCFF Build'!F25,'FCFF Build'!G25)+'Income Stmt'!G23*E17/(1+$A21)^5+Assumptions!D28)/Assumptions!D29 -> 2149.4181 | F21: =(NPV($A21,'FCFF Build'!C25,'FCFF Build'!D25,'FCFF Build'!E25,'FCFF Build'!F25,'FCFF Build'!G25)+'Income Stmt'!G23*F17/(1+$A21)^5+Assumptions!D28)/Assumptions!D29 -> 2319.0397 | G21: =(NPV($A21,'FCFF Build'!C25,'FCFF Build'!D25,'FCFF Build'!E25,'FCFF Build'!F25,'FCFF Build'!G25)+'Income Stmt'!G23*G17/(1+$A21)^5+Assumptions!D28)/Assumptions!D29 -> 2488.6612 | H21: =(NPV($A21,'FCFF Build'!C25,'FCFF Build'!D25,'FCFF Build'!E25,'FCFF Build'!F25,'FCFF Build'!G25)+'Income Stmt'!G23*H17/(1+$A21)^5+Assumptions!D28)/Assumptions!D29 -> 2601.7423
A22: 0.105 | B22: =(NPV($A22,'FCFF Build'!C25,'FCFF Build'!D25,'FCFF Build'!E25,'FCFF Build'!F25,'FCFF Build'!G25)+'Income Stmt'!G23*B17/(1+$A22)^5+Assumptions!D28)/Assumptions!D29 -> 1718.9603 | C22: =(NPV($A22,'FCFF Build'!C25,'FCFF Build'!D25,'FCFF Build'!E25,'FCFF Build'!F25,'FCFF Build'!G25)+'Income Stmt'!G23*C17/(1+$A22)^5+Assumptions!D28)/Assumptions!D29 -> 1884.7789 | D22: =(NPV($A22,'FCFF Build'!C25,'FCFF Build'!D25,'FCFF Build'!E25,'FCFF Build'!F25,'FCFF Build'!G25)+'Income Stmt'!G23*D17/(1+$A22)^5+Assumptions!D28)/Assumptions!D29 -> 1995.3246 | E22: =(NPV($A22,'FCFF Build'!C25,'FCFF Build'!D25,'FCFF Build'!E25,'FCFF Build'!F25,'FCFF Build'!G25)+'Income Stmt'!G23*E17/(1+$A22)^5+Assumptions!D28)/Assumptions!D29 -> 2105.8703 | F22: =(NPV($A22,'FCFF Build'!C25,'FCFF Build'!D25,'FCFF Build'!E25,'FCFF Build'!F25,'FCFF Build'!G25)+'Income Stmt'!G23*F17/(1+$A22)^5+Assumptions!D28)/Assumptions!D29 -> 2271.6888 | G22: =(NPV($A22,'FCFF Build'!C25,'FCFF Build'!D25,'FCFF Build'!E25,'FCFF Build'!F25,'FCFF Build'!G25)+'Income Stmt'!G23*G17/(1+$A22)^5+Assumptions!D28)/Assumptions!D29 -> 2437.5074 | H22: =(NPV($A22,'FCFF Build'!C25,'FCFF Build'!D25,'FCFF Build'!E25,'FCFF Build'!F25,'FCFF Build'!G25)+'Income Stmt'!G23*H17/(1+$A22)^5+Assumptions!D28)/Assumptions!D29 -> 2548.0531
A23: 0.11 | B23: =(NPV($A23,'FCFF Build'!C25,'FCFF Build'!D25,'FCFF Build'!E25,'FCFF Build'!F25,'FCFF Build'!G25)+'Income Stmt'!G23*B17/(1+$A23)^5+Assumptions!D28)/Assumptions!D29 -> 1685.1967 | C23: =(NPV($A23,'FCFF Build'!C25,'FCFF Build'!D25,'FCFF Build'!E25,'FCFF Build'!F25,'FCFF Build'!G25)+'Income Stmt'!G23*C17/(1+$A23)^5+Assumptions!D28)/Assumptions!D29 -> 1847.3141 | D23: =(NPV($A23,'FCFF Build'!C25,'FCFF Build'!D25,'FCFF Build'!E25,'FCFF Build'!F25,'FCFF Build'!G25)+'Income Stmt'!G23*D17/(1+$A23)^5+Assumptions!D28)/Assumptions!D29 -> 1955.3923 | E23: =(NPV($A23,'FCFF Build'!C25,'FCFF Build'!D25,'FCFF Build'!E25,'FCFF Build'!F25,'FCFF Build'!G25)+'Income Stmt'!G23*E17/(1+$A23)^5+Assumptions!D28)/Assumptions!D29 -> 2063.4706 | F23: =(NPV($A23,'FCFF Build'!C25,'FCFF Build'!D25,'FCFF Build'!E25,'FCFF Build'!F25,'FCFF Build'!G25)+'Income Stmt'!G23*F17/(1+$A23)^5+Assumptions!D28)/Assumptions!D29 -> 2225.588 | G23: =(NPV($A23,'FCFF Build'!C25,'FCFF Build'!D25,'FCFF Build'!E25,'FCFF Build'!F25,'FCFF Build'!G25)+'Income Stmt'!G23*G17/(1+$A23)^5+Assumptions!D28)/Assumptions!D29 -> 2387.7054 | H23: =(NPV($A23,'FCFF Build'!C25,'FCFF Build'!D25,'FCFF Build'!E25,'FCFF Build'!F25,'FCFF Build'!G25)+'Income Stmt'!G23*H17/(1+$A23)^5+Assumptions!D28)/Assumptions!D29 -> 2495.7836
A24: 0.115 | B24: =(NPV($A24,'FCFF Build'!C25,'FCFF Build'!D25,'FCFF Build'!E25,'FCFF Build'!F25,'FCFF Build'!G25)+'Income Stmt'!G23*B17/(1+$A24)^5+Assumptions!D28)/Assumptions!D29 -> 1652.3155 | C24: =(NPV($A24,'FCFF Build'!C25,'FCFF Build'!D25,'FCFF Build'!E25,'FCFF Build'!F25,'FCFF Build'!G25)+'Income Stmt'!G23*C17/(1+$A24)^5+Assumptions!D28)/Assumptions!D29 -> 1810.8304 | D24: =(NPV($A24,'FCFF Build'!C25,'FCFF Build'!D25,'FCFF Build'!E25,'FCFF Build'!F25,'FCFF Build'!G25)+'Income Stmt'!G23*D17/(1+$A24)^5+Assumptions!D28)/Assumptions!D29 -> 1916.5071 | E24: =(NPV($A24,'FCFF Build'!C25,'FCFF Build'!D25,'FCFF Build'!E25,'FCFF Build'!F25,'FCFF Build'!G25)+'Income Stmt'!G23*E17/(1+$A24)^5+Assumptions!D28)/Assumptions!D29 -> 2022.1837 | F24: =(NPV($A24,'FCFF Build'!C25,'FCFF Build'!D25,'FCFF Build'!E25,'FCFF Build'!F25,'FCFF Build'!G25)+'Income Stmt'!G23*F17/(1+$A24)^5+Assumptions!D28)/Assumptions!D29 -> 2180.6986 | G24: =(NPV($A24,'FCFF Build'!C25,'FCFF Build'!D25,'FCFF Build'!E25,'FCFF Build'!F25,'FCFF Build'!G25)+'Income Stmt'!G23*G17/(1+$A24)^5+Assumptions!D28)/Assumptions!D29 -> 2339.2135 | H24: =(NPV($A24,'FCFF Build'!C25,'FCFF Build'!D25,'FCFF Build'!E25,'FCFF Build'!F25,'FCFF Build'!G25)+'Income Stmt'!G23*H17/(1+$A24)^5+Assumptions!D28)/Assumptions!D29 -> 2444.8901
A26: Both grids use Base Case FCFF projections only. Net cash ₹2,944 Cr added to EV in bridge.

Sheet Reverse DCF
A1: Reverse DCF — What Does ₹2,885 Imply?
A2: Given today's share price, what revenue CAGR is the market pricing in? (Base margins & WACC assumed)
A4: CURRENT MARKET PRICE (MCX, 16 Jun 2026)
A5: Current Share Price (₹/share) | B5: =Assumptions!D30 -> 2885
A6: Shares Outstanding (Cr) | B6: =Assumptions!D29 -> 25.5
A7: Implied Market Cap (₹ Cr) | B7: =B5*B6 -> 73567.5
A8: Less: Net Cash (MCX is net cash) | B8: =Assumptions!D28 -> 2944
A9: Implied Enterprise Value (₹ Cr) | B9: =B7-B8 -> 70623.5
A11: WHAT REVENUE CAGR DOES THE MARKET REQUIRE?
A12: We test revenue CAGRs and compute implied EV (Base margins, Base WACC, Base terminal assumptions).
A13: Test Revenue CAGR (Y1-Y5) | B13: Implied EV (₹ Cr) | C13: vs Market EV (₹ Cr) | D13: Implied Share Price (₹)
A14: 0.05 | B14: =((((Assumptions!$D$6*(1+$A14)^1)*(Assumptions!$D$14+(Assumptions!$D$19-Assumptions!$D$14)*1/5))-((Assumptions!$D$6*(1+$A14)^1)*Assumptions!$D$22))*(1-Assumptions!$D$27)+((Assumptions!$D$6*(1+$A14)^1)*Assumptions!$D$22)-((Assumptions!$D$6*(1+$A14)^1)*Assumptions!$D$23)-(((Assumptions!$D$6*(1+$A14)^1)-Assumptions!$D$6)*Assumptions!$D$24))/(1+WACC!$D$21)^1+((((Assumptions!$D$6*(1+$A14)^2)*(Assumptions!$D$14+(Assumptions!$D$19-Assumptions!$D$14)*2/5))-((Assumptions!$D$6*(1+$A14)^2)*Assumptions!$D$22))*(1-Assumptions!$D$27)+((Assumptions!$D$6*(1+$A14)^2)*Assumptions!$D$22)-((Assumptions!$D$6*(1+$A14)^2)*Assumptions!$D$23)-(((Assumptions!$D$6*(1+$A14)^2)-(Assumptions!$D$6*(1+$A14)^1))*Assumptions!$D$24))/(1+WACC!$D$21)^2+((((Assumptions!$D$6*(1+$A14)^3)*(Assumptions!$D$14+(Assumptions!$D$19-Assumptions!$D$14)*3/5))-((Assumptions!$D$6*(1+$A14)^3)*Assumptions!$D$22))*(1-Assumptions!$D$27)+((Assumptions!$D$6*(1+$A14)^3)*Assumptions!$D$22)-((Assumptions!$D$6*(1+$A14)^3)*Assumptions!$D$23)-(((Assumptions!$D$6*(1+$A14)^3)-(Assumptions!$D$6*(1+$A14)^2))*Assumptions!$D$24))/(1+WACC!$D$21)^3+((((Assumptions!$D$6*(1+$A14)^4)*(Assumptions!$D$14+(Assumptions!$D$19-Assumptions!$D$14)*4/5))-((Assumptions!$D$6*(1+$A14)^4)*Assumptions!$D$22))*(1-Assumptions!$D$27)+((Assumptions!$D$6*(1+$A14)^4)*Assumptions!$D$22)-((Assumptions!$D$6*(1+$A14)^4)*Assumptions!$D$23)-(((Assumptions!$D$6*(1+$A14)^4)-(Assumptions!$D$6*(1+$A14)^3))*Assumptions!$D$24))/(1+WACC!$D$21)^4+((((Assumptions!$D$6*(1+$A14)^5)*(Assumptions!$D$14+(Assumptions!$D$19-Assumptions!$D$14)*5/5))-((Assumptions!$D$6*(1+$A14)^5)*Assumptions!$D$22))*(1-Assumptions!$D$27)+((Assumptions!$D$6*(1+$A14)^5)*Assumptions!$D$22)-((Assumptions!$D$6*(1+$A14)^5)*Assumptions!$D$23)-(((Assumptions!$D$6*(1+$A14)^5)-(Assumptions!$D$6*(1+$A14)^4))*Assumptions!$D$24))/(1+WACC!$D$21)^5+(((Assumptions!$D$6*(1+$A14)^5)*Assumptions!$D$19)*Assumptions!$D$41/(1+WACC!$D$21)^5) -> 40935.434 | C14: =B14-$B$9 -> -29688.066 | D14: =(B14+Assumptions!$D$28)/Assumptions!$D$29 -> 1720.7621
A15: 0.08 | B15: =((((Assumptions!$D$6*(1+$A15)^1)*(Assumptions!$D$14+(Assumptions!$D$19-Assumptions!$D$14)*1/5))-((Assumptions!$D$6*(1+$A15)^1)*Assumptions!$D$22))*(1-Assumptions!$D$27)+((Assumptions!$D$6*(1+$A15)^1)*Assumptions!$D$22)-((Assumptions!$D$6*(1+$A15)^1)*Assumptions!$D$23)-(((Assumptions!$D$6*(1+$A15)^1)-Assumptions!$D$6)*Assumptions!$D$24))/(1+WACC!$D$21)^1+((((Assumptions!$D$6*(1+$A15)^2)*(Assumptions!$D$14+(Assumptions!$D$19-Assumptions!$D$14)*2/5))-((Assumptions!$D$6*(1+$A15)^2)*Assumptions!$D$22))*(1-Assumptions!$D$27)+((Assumptions!$D$6*(1+$A15)^2)*Assumptions!$D$22)-((Assumptions!$D$6*(1+$A15)^2)*Assumptions!$D$23)-(((Assumptions!$D$6*(1+$A15)^2)-(Assumptions!$D$6*(1+$A15)^1))*Assumptions!$D$24))/(1+WACC!$D$21)^2+((((Assumptions!$D$6*(1+$A15)^3)*(Assumptions!$D$14+(Assumptions!$D$19-Assumptions!$D$14)*3/5))-((Assumptions!$D$6*(1+$A15)^3)*Assumptions!$D$22))*(1-Assumptions!$D$27)+((Assumptions!$D$6*(1+$A15)^3)*Assumptions!$D$22)-((Assumptions!$D$6*(1+$A15)^3)*Assumptions!$D$23)-(((Assumptions!$D$6*(1+$A15)^3)-(Assumptions!$D$6*(1+$A15)^2))*Assumptions!$D$24))/(1+WACC!$D$21)^3+((((Assumptions!$D$6*(1+$A15)^4)*(Assumptions!$D$14+(Assumptions!$D$19-Assumptions!$D$14)*4/5))-((Assumptions!$D$6*(1+$A15)^4)*Assumptions!$D$22))*(1-Assumptions!$D$27)+((Assumptions!$D$6*(1+$A15)^4)*Assumptions!$D$22)-((Assumptions!$D$6*(1+$A15)^4)*Assumptions!$D$23)-(((Assumptions!$D$6*(1+$A15)^4)-(Assumptions!$D$6*(1+$A15)^3))*Assumptions!$D$24))/(1+WACC!$D$21)^4+((((Assumptions!$D$6*(1+$A15)^5)*(Assumptions!$D$14+(Assumptions!$D$19-Assumptions!$D$14)*5/5))-((Assumptions!$D$6*(1+$A15)^5)*Assumptions!$D$22))*(1-Assumptions!$D$27)+((Assumptions!$D$6*(1+$A15)^5)*Assumptions!$D$22)-((Assumptions!$D$6*(1+$A15)^5)*Assumptions!$D$23)-(((Assumptions!$D$6*(1+$A15)^5)-(Assumptions!$D$6*(1+$A15)^4))*Assumptions!$D$24))/(1+WACC!$D$21)^5+(((Assumptions!$D$6*(1+$A15)^5)*Assumptions!$D$19)*Assumptions!$D$41/(1+WACC!$D$21)^5) -> 46795.463 | C15: =B15-$B$9 -> -23828.037 | D15: =(B15+Assumptions!$D$28)/Assumptions!$D$29 -> 1950.5672
A16: 0.1 | B16: =((((Assumptions!$D$6*(1+$A16)^1)*(Assumptions!$D$14+(Assumptions!$D$19-Assumptions!$D$14)*1/5))-((Assumptions!$D$6*(1+$A16)^1)*Assumptions!$D$22))*(1-Assumptions!$D$27)+((Assumptions!$D$6*(1+$A16)^1)*Assumptions!$D$22)-((Assumptions!$D$6*(1+$A16)^1)*Assumptions!$D$23)-(((Assumptions!$D$6*(1+$A16)^1)-Assumptions!$D$6)*Assumptions!$D$24))/(1+WACC!$D$21)^1+((((Assumptions!$D$6*(1+$A16)^2)*(Assumptions!$D$14+(Assumptions!$D$19-Assumptions!$D$14)*2/5))-((Assumptions!$D$6*(1+$A16)^2)*Assumptions!$D$22))*(1-Assumptions!$D$27)+((Assumptions!$D$6*(1+$A16)^2)*Assumptions!$D$22)-((Assumptions!$D$6*(1+$A16)^2)*Assumptions!$D$23)-(((Assumptions!$D$6*(1+$A16)^2)-(Assumptions!$D$6*(1+$A16)^1))*Assumptions!$D$24))/(1+WACC!$D$21)^2+((((Assumptions!$D$6*(1+$A16)^3)*(Assumptions!$D$14+(Assumptions!$D$19-Assumptions!$D$14)*3/5))-((Assumptions!$D$6*(1+$A16)^3)*Assumptions!$D$22))*(1-Assumptions!$D$27)+((Assumptions!$D$6*(1+$A16)^3)*Assumptions!$D$22)-((Assumptions!$D$6*(1+$A16)^3)*Assumptions!$D$23)-(((Assumptions!$D$6*(1+$A16)^3)-(Assumptions!$D$6*(1+$A16)^2))*Assumptions!$D$24))/(1+WACC!$D$21)^3+((((Assumptions!$D$6*(1+$A16)^4)*(Assumptions!$D$14+(Assumptions!$D$19-Assumptions!$D$14)*4/5))-((Assumptions!$D$6*(1+$A16)^4)*Assumptions!$D$22))*(1-Assumptions!$D$27)+((Assumptions!$D$6*(1+$A16)^4)*Assumptions!$D$22)-((Assumptions!$D$6*(1+$A16)^4)*Assumptions!$D$23)-(((Assumptions!$D$6*(1+$A16)^4)-(Assumptions!$D$6*(1+$A16)^3))*Assumptions!$D$24))/(1+WACC!$D$21)^4+((((Assumptions!$D$6*(1+$A16)^5)*(Assumptions!$D$14+(Assumptions!$D$19-Assumptions!$D$14)*5/5))-((Assumptions!$D$6*(1+$A16)^5)*Assumptions!$D$22))*(1-Assumptions!$D$27)+((Assumptions!$D$6*(1+$A16)^5)*Assumptions!$D$22)-((Assumptions!$D$6*(1+$A16)^5)*Assumptions!$D$23)-(((Assumptions!$D$6*(1+$A16)^5)-(Assumptions!$D$6*(1+$A16)^4))*Assumptions!$D$24))/(1+WACC!$D$21)^5+(((Assumptions!$D$6*(1+$A16)^5)*Assumptions!$D$19)*Assumptions!$D$41/(1+WACC!$D$21)^5) -> 51071.498 | C16: =B16-$B$9 -> -19552.002 | D16: =(B16+Assumptions!$D$28)/Assumptions!$D$29 -> 2118.2548
A17: 0.12 | B17: =((((Assumptions!$D$6*(1+$A17)^1)*(Assumptions!$D$14+(Assumptions!$D$19-Assumptions!$D$14)*1/5))-((Assumptions!$D$6*(1+$A17)^1)*Assumptions!$D$22))*(1-Assumptions!$D$27)+((Assumptions!$D$6*(1+$A17)^1)*Assumptions!$D$22)-((Assumptions!$D$6*(1+$A17)^1)*Assumptions!$D$23)-(((Assumptions!$D$6*(1+$A17)^1)-Assumptions!$D$6)*Assumptions!$D$24))/(1+WACC!$D$21)^1+((((Assumptions!$D$6*(1+$A17)^2)*(Assumptions!$D$14+(Assumptions!$D$19-Assumptions!$D$14)*2/5))-((Assumptions!$D$6*(1+$A17)^2)*Assumptions!$D$22))*(1-Assumptions!$D$27)+((Assumptions!$D$6*(1+$A17)^2)*Assumptions!$D$22)-((Assumptions!$D$6*(1+$A17)^2)*Assumptions!$D$23)-(((Assumptions!$D$6*(1+$A17)^2)-(Assumptions!$D$6*(1+$A17)^1))*Assumptions!$D$24))/(1+WACC!$D$21)^2+((((Assumptions!$D$6*(1+$A17)^3)*(Assumptions!$D$14+(Assumptions!$D$19-Assumptions!$D$14)*3/5))-((Assumptions!$D$6*(1+$A17)^3)*Assumptions!$D$22))*(1-Assumptions!$D$27)+((Assumptions!$D$6*(1+$A17)^3)*Assumptions!$D$22)-((Assumptions!$D$6*(1+$A17)^3)*Assumptions!$D$23)-(((Assumptions!$D$6*(1+$A17)^3)-(Assumptions!$D$6*(1+$A17)^2))*Assumptions!$D$24))/(1+WACC!$D$21)^3+((((Assumptions!$D$6*(1+$A17)^4)*(Assumptions!$D$14+(Assumptions!$D$19-Assumptions!$D$14)*4/5))-((Assumptions!$D$6*(1+$A17)^4)*Assumptions!$D$22))*(1-Assumptions!$D$27)+((Assumptions!$D$6*(1+$A17)^4)*Assumptions!$D$22)-((Assumptions!$D$6*(1+$A17)^4)*Assumptions!$D$23)-(((Assumptions!$D$6*(1+$A17)^4)-(Assumptions!$D$6*(1+$A17)^3))*Assumptions!$D$24))/(1+WACC!$D$21)^4+((((Assumptions!$D$6*(1+$A17)^5)*(Assumptions!$D$14+(Assumptions!$D$19-Assumptions!$D$14)*5/5))-((Assumptions!$D$6*(1+$A17)^5)*Assumptions!$D$22))*(1-Assumptions!$D$27)+((Assumptions!$D$6*(1+$A17)^5)*Assumptions!$D$22)-((Assumptions!$D$6*(1+$A17)^5)*Assumptions!$D$23)-(((Assumptions!$D$6*(1+$A17)^5)-(Assumptions!$D$6*(1+$A17)^4))*Assumptions!$D$24))/(1+WACC!$D$21)^5+(((Assumptions!$D$6*(1+$A17)^5)*Assumptions!$D$19)*Assumptions!$D$41/(1+WACC!$D$21)^5) -> 55662.375 | C17: =B17-$B$9 -> -14961.125 | D17: =(B17+Assumptions!$D$28)/Assumptions!$D$29 -> 2298.2892
A18: 0.15 | B18: =((((Assumptions!$D$6*(1+$A18)^1)*(Assumptions!$D$14+(Assumptions!$D$19-Assumptions!$D$14)*1/5))-((Assumptions!$D$6*(1+$A18)^1)*Assumptions!$D$22))*(1-Assumptions!$D$27)+((Assumptions!$D$6*(1+$A18)^1)*Assumptions!$D$22)-((Assumptions!$D$6*(1+$A18)^1)*Assumptions!$D$23)-(((Assumptions!$D$6*(1+$A18)^1)-Assumptions!$D$6)*Assumptions!$D$24))/(1+WACC!$D$21)^1+((((Assumptions!$D$6*(1+$A18)^2)*(Assumptions!$D$14+(Assumptions!$D$19-Assumptions!$D$14)*2/5))-((Assumptions!$D$6*(1+$A18)^2)*Assumptions!$D$22))*(1-Assumptions!$D$27)+((Assumptions!$D$6*(1+$A18)^2)*Assumptions!$D$22)-((Assumptions!$D$6*(1+$A18)^2)*Assumptions!$D$23)-(((Assumptions!$D$6*(1+$A18)^2)-(Assumptions!$D$6*(1+$A18)^1))*Assumptions!$D$24))/(1+WACC!$D$21)^2+((((Assumptions!$D$6*(1+$A18)^3)*(Assumptions!$D$14+(Assumptions!$D$19-Assumptions!$D$14)*3/5))-((Assumptions!$D$6*(1+$A18)^3)*Assumptions!$D$22))*(1-Assumptions!$D$27)+((Assumptions!$D$6*(1+$A18)^3)*Assumptions!$D$22)-((Assumptions!$D$6*(1+$A18)^3)*Assumptions!$D$23)-(((Assumptions!$D$6*(1+$A18)^3)-(Assumptions!$D$6*(1+$A18)^2))*Assumptions!$D$24))/(1+WACC!$D$21)^3+((((Assumptions!$D$6*(1+$A18)^4)*(Assumptions!$D$14+(Assumptions!$D$19-Assumptions!$D$14)*4/5))-((Assumptions!$D$6*(1+$A18)^4)*Assumptions!$D$22))*(1-Assumptions!$D$27)+((Assumptions!$D$6*(1+$A18)^4)*Assumptions!$D$22)-((Assumptions!$D$6*(1+$A18)^4)*Assumptions!$D$23)-(((Assumptions!$D$6*(1+$A18)^4)-(Assumptions!$D$6*(1+$A18)^3))*Assumptions!$D$24))/(1+WACC!$D$21)^4+((((Assumptions!$D$6*(1+$A18)^5)*(Assumptions!$D$14+(Assumptions!$D$19-Assumptions!$D$14)*5/5))-((Assumptions!$D$6*(1+$A18)^5)*Assumptions!$D$22))*(1-Assumptions!$D$27)+((Assumptions!$D$6*(1+$A18)^5)*Assumptions!$D$22)-((Assumptions!$D$6*(1+$A18)^5)*Assumptions!$D$23)-(((Assumptions!$D$6*(1+$A18)^5)-(Assumptions!$D$6*(1+$A18)^4))*Assumptions!$D$24))/(1+WACC!$D$21)^5+(((Assumptions!$D$6*(1+$A18)^5)*Assumptions!$D$19)*Assumptions!$D$41/(1+WACC!$D$21)^5) -> 63176.999 | C18: =B18-$B$9 -> -7446.5005 | D18: =(B18+Assumptions!$D$28)/Assumptions!$D$29 -> 2592.9804
A19: 0.18 | B19: =((((Assumptions!$D$6*(1+$A19)^1)*(Assumptions!$D$14+(Assumptions!$D$19-Assumptions!$D$14)*1/5))-((Assumptions!$D$6*(1+$A19)^1)*Assumptions!$D$22))*(1-Assumptions!$D$27)+((Assumptions!$D$6*(1+$A19)^1)*Assumptions!$D$22)-((Assumptions!$D$6*(1+$A19)^1)*Assumptions!$D$23)-(((Assumptions!$D$6*(1+$A19)^1)-Assumptions!$D$6)*Assumptions!$D$24))/(1+WACC!$D$21)^1+((((Assumptions!$D$6*(1+$A19)^2)*(Assumptions!$D$14+(Assumptions!$D$19-Assumptions!$D$14)*2/5))-((Assumptions!$D$6*(1+$A19)^2)*Assumptions!$D$22))*(1-Assumptions!$D$27)+((Assumptions!$D$6*(1+$A19)^2)*Assumptions!$D$22)-((Assumptions!$D$6*(1+$A19)^2)*Assumptions!$D$23)-(((Assumptions!$D$6*(1+$A19)^2)-(Assumptions!$D$6*(1+$A19)^1))*Assumptions!$D$24))/(1+WACC!$D$21)^2+((((Assumptions!$D$6*(1+$A19)^3)*(Assumptions!$D$14+(Assumptions!$D$19-Assumptions!$D$14)*3/5))-((Assumptions!$D$6*(1+$A19)^3)*Assumptions!$D$22))*(1-Assumptions!$D$27)+((Assumptions!$D$6*(1+$A19)^3)*Assumptions!$D$22)-((Assumptions!$D$6*(1+$A19)^3)*Assumptions!$D$23)-(((Assumptions!$D$6*(1+$A19)^3)-(Assumptions!$D$6*(1+$A19)^2))*Assumptions!$D$24))/(1+WACC!$D$21)^3+((((Assumptions!$D$6*(1+$A19)^4)*(Assumptions!$D$14+(Assumptions!$D$19-Assumptions!$D$14)*4/5))-((Assumptions!$D$6*(1+$A19)^4)*Assumptions!$D$22))*(1-Assumptions!$D$27)+((Assumptions!$D$6*(1+$A19)^4)*Assumptions!$D$22)-((Assumptions!$D$6*(1+$A19)^4)*Assumptions!$D$23)-(((Assumptions!$D$6*(1+$A19)^4)-(Assumptions!$D$6*(1+$A19)^3))*Assumptions!$D$24))/(1+WACC!$D$21)^4+((((Assumptions!$D$6*(1+$A19)^5)*(Assumptions!$D$14+(Assumptions!$D$19-Assumptions!$D$14)*5/5))-((Assumptions!$D$6*(1+$A19)^5)*Assumptions!$D$22))*(1-Assumptions!$D$27)+((Assumptions!$D$6*(1+$A19)^5)*Assumptions!$D$22)-((Assumptions!$D$6*(1+$A19)^5)*Assumptions!$D$23)-(((Assumptions!$D$6*(1+$A19)^5)-(Assumptions!$D$6*(1+$A19)^4))*Assumptions!$D$24))/(1+WACC!$D$21)^5+(((Assumptions!$D$6*(1+$A19)^5)*Assumptions!$D$19)*Assumptions!$D$41/(1+WACC!$D$21)^5) -> 71500.038 | C19: =B19-$B$9 -> 876.53757 | D19: =(B19+Assumptions!$D$28)/Assumptions!$D$29 -> 2919.374
A20: 0.2 | B20: =((((Assumptions!$D$6*(1+$A20)^1)*(Assumptions!$D$14+(Assumptions!$D$19-Assumptions!$D$14)*1/5))-((Assumptions!$D$6*(1+$A20)^1)*Assumptions!$D$22))*(1-Assumptions!$D$27)+((Assumptions!$D$6*(1+$A20)^1)*Assumptions!$D$22)-((Assumptions!$D$6*(1+$A20)^1)*Assumptions!$D$23)-(((Assumptions!$D$6*(1+$A20)^1)-Assumptions!$D$6)*Assumptions!$D$24))/(1+WACC!$D$21)^1+((((Assumptions!$D$6*(1+$A20)^2)*(Assumptions!$D$14+(Assumptions!$D$19-Assumptions!$D$14)*2/5))-((Assumptions!$D$6*(1+$A20)^2)*Assumptions!$D$22))*(1-Assumptions!$D$27)+((Assumptions!$D$6*(1+$A20)^2)*Assumptions!$D$22)-((Assumptions!$D$6*(1+$A20)^2)*Assumptions!$D$23)-(((Assumptions!$D$6*(1+$A20)^2)-(Assumptions!$D$6*(1+$A20)^1))*Assumptions!$D$24))/(1+WACC!$D$21)^2+((((Assumptions!$D$6*(1+$A20)^3)*(Assumptions!$D$14+(Assumptions!$D$19-Assumptions!$D$14)*3/5))-((Assumptions!$D$6*(1+$A20)^3)*Assumptions!$D$22))*(1-Assumptions!$D$27)+((Assumptions!$D$6*(1+$A20)^3)*Assumptions!$D$22)-((Assumptions!$D$6*(1+$A20)^3)*Assumptions!$D$23)-(((Assumptions!$D$6*(1+$A20)^3)-(Assumptions!$D$6*(1+$A20)^2))*Assumptions!$D$24))/(1+WACC!$D$21)^3+((((Assumptions!$D$6*(1+$A20)^4)*(Assumptions!$D$14+(Assumptions!$D$19-Assumptions!$D$14)*4/5))-((Assumptions!$D$6*(1+$A20)^4)*Assumptions!$D$22))*(1-Assumptions!$D$27)+((Assumptions!$D$6*(1+$A20)^4)*Assumptions!$D$22)-((Assumptions!$D$6*(1+$A20)^4)*Assumptions!$D$23)-(((Assumptions!$D$6*(1+$A20)^4)-(Assumptions!$D$6*(1+$A20)^3))*Assumptions!$D$24))/(1+WACC!$D$21)^4+((((Assumptions!$D$6*(1+$A20)^5)*(Assumptions!$D$14+(Assumptions!$D$19-Assumptions!$D$14)*5/5))-((Assumptions!$D$6*(1+$A20)^5)*Assumptions!$D$22))*(1-Assumptions!$D$27)+((Assumptions!$D$6*(1+$A20)^5)*Assumptions!$D$22)-((Assumptions!$D$6*(1+$A20)^5)*Assumptions!$D$23)-(((Assumptions!$D$6*(1+$A20)^5)-(Assumptions!$D$6*(1+$A20)^4))*Assumptions!$D$24))/(1+WACC!$D$21)^5+(((Assumptions!$D$6*(1+$A20)^5)*Assumptions!$D$19)*Assumptions!$D$41/(1+WACC!$D$21)^5) -> 77529.429 | C20: =B20-$B$9 -> 6905.9292 | D20: =(B20+Assumptions!$D$28)/Assumptions!$D$29 -> 3155.8208
A21: 0.25 | B21: =((((Assumptions!$D$6*(1+$A21)^1)*(Assumptions!$D$14+(Assumptions!$D$19-Assumptions!$D$14)*1/5))-((Assumptions!$D$6*(1+$A21)^1)*Assumptions!$D$22))*(1-Assumptions!$D$27)+((Assumptions!$D$6*(1+$A21)^1)*Assumptions!$D$22)-((Assumptions!$D$6*(1+$A21)^1)*Assumptions!$D$23)-(((Assumptions!$D$6*(1+$A21)^1)-Assumptions!$D$6)*Assumptions!$D$24))/(1+WACC!$D$21)^1+((((Assumptions!$D$6*(1+$A21)^2)*(Assumptions!$D$14+(Assumptions!$D$19-Assumptions!$D$14)*2/5))-((Assumptions!$D$6*(1+$A21)^2)*Assumptions!$D$22))*(1-Assumptions!$D$27)+((Assumptions!$D$6*(1+$A21)^2)*Assumptions!$D$22)-((Assumptions!$D$6*(1+$A21)^2)*Assumptions!$D$23)-(((Assumptions!$D$6*(1+$A21)^2)-(Assumptions!$D$6*(1+$A21)^1))*Assumptions!$D$24))/(1+WACC!$D$21)^2+((((Assumptions!$D$6*(1+$A21)^3)*(Assumptions!$D$14+(Assumptions!$D$19-Assumptions!$D$14)*3/5))-((Assumptions!$D$6*(1+$A21)^3)*Assumptions!$D$22))*(1-Assumptions!$D$27)+((Assumptions!$D$6*(1+$A21)^3)*Assumptions!$D$22)-((Assumptions!$D$6*(1+$A21)^3)*Assumptions!$D$23)-(((Assumptions!$D$6*(1+$A21)^3)-(Assumptions!$D$6*(1+$A21)^2))*Assumptions!$D$24))/(1+WACC!$D$21)^3+((((Assumptions!$D$6*(1+$A21)^4)*(Assumptions!$D$14+(Assumptions!$D$19-Assumptions!$D$14)*4/5))-((Assumptions!$D$6*(1+$A21)^4)*Assumptions!$D$22))*(1-Assumptions!$D$27)+((Assumptions!$D$6*(1+$A21)^4)*Assumptions!$D$22)-((Assumptions!$D$6*(1+$A21)^4)*Assumptions!$D$23)-(((Assumptions!$D$6*(1+$A21)^4)-(Assumptions!$D$6*(1+$A21)^3))*Assumptions!$D$24))/(1+WACC!$D$21)^4+((((Assumptions!$D$6*(1+$A21)^5)*(Assumptions!$D$14+(Assumptions!$D$19-Assumptions!$D$14)*5/5))-((Assumptions!$D$6*(1+$A21)^5)*Assumptions!$D$22))*(1-Assumptions!$D$27)+((Assumptions!$D$6*(1+$A21)^5)*Assumptions!$D$22)-((Assumptions!$D$6*(1+$A21)^5)*Assumptions!$D$23)-(((Assumptions!$D$6*(1+$A21)^5)-(Assumptions!$D$6*(1+$A21)^4))*Assumptions!$D$24))/(1+WACC!$D$21)^5+(((Assumptions!$D$6*(1+$A21)^5)*Assumptions!$D$19)*Assumptions!$D$41/(1+WACC!$D$21)^5) -> 94431.314 | C21: =B21-$B$9 -> 23807.814 | D21: =(B21+Assumptions!$D$28)/Assumptions!$D$29 -> 3818.6398
A22: 0.3 | B22: =((((Assumptions!$D$6*(1+$A22)^1)*(Assumptions!$D$14+(Assumptions!$D$19-Assumptions!$D$14)*1/5))-((Assumptions!$D$6*(1+$A22)^1)*Assumptions!$D$22))*(1-Assumptions!$D$27)+((Assumptions!$D$6*(1+$A22)^1)*Assumptions!$D$22)-((Assumptions!$D$6*(1+$A22)^1)*Assumptions!$D$23)-(((Assumptions!$D$6*(1+$A22)^1)-Assumptions!$D$6)*Assumptions!$D$24))/(1+WACC!$D$21)^1+((((Assumptions!$D$6*(1+$A22)^2)*(Assumptions!$D$14+(Assumptions!$D$19-Assumptions!$D$14)*2/5))-((Assumptions!$D$6*(1+$A22)^2)*Assumptions!$D$22))*(1-Assumptions!$D$27)+((Assumptions!$D$6*(1+$A22)^2)*Assumptions!$D$22)-((Assumptions!$D$6*(1+$A22)^2)*Assumptions!$D$23)-(((Assumptions!$D$6*(1+$A22)^2)-(Assumptions!$D$6*(1+$A22)^1))*Assumptions!$D$24))/(1+WACC!$D$21)^2+((((Assumptions!$D$6*(1+$A22)^3)*(Assumptions!$D$14+(Assumptions!$D$19-Assumptions!$D$14)*3/5))-((Assumptions!$D$6*(1+$A22)^3)*Assumptions!$D$22))*(1-Assumptions!$D$27)+((Assumptions!$D$6*(1+$A22)^3)*Assumptions!$D$22)-((Assumptions!$D$6*(1+$A22)^3)*Assumptions!$D$23)-(((Assumptions!$D$6*(1+$A22)^3)-(Assumptions!$D$6*(1+$A22)^2))*Assumptions!$D$24))/(1+WACC!$D$21)^3+((((Assumptions!$D$6*(1+$A22)^4)*(Assumptions!$D$14+(Assumptions!$D$19-Assumptions!$D$14)*4/5))-((Assumptions!$D$6*(1+$A22)^4)*Assumptions!$D$22))*(1-Assumptions!$D$27)+((Assumptions!$D$6*(1+$A22)^4)*Assumptions!$D$22)-((Assumptions!$D$6*(1+$A22)^4)*Assumptions!$D$23)-(((Assumptions!$D$6*(1+$A22)^4)-(Assumptions!$D$6*(1+$A22)^3))*Assumptions!$D$24))/(1+WACC!$D$21)^4+((((Assumptions!$D$6*(1+$A22)^5)*(Assumptions!$D$14+(Assumptions!$D$19-Assumptions!$D$14)*5/5))-((Assumptions!$D$6*(1+$A22)^5)*Assumptions!$D$22))*(1-Assumptions!$D$27)+((Assumptions!$D$6*(1+$A22)^5)*Assumptions!$D$22)-((Assumptions!$D$6*(1+$A22)^5)*Assumptions!$D$23)-(((Assumptions!$D$6*(1+$A22)^5)-(Assumptions!$D$6*(1+$A22)^4))*Assumptions!$D$24))/(1+WACC!$D$21)^5+(((Assumptions!$D$6*(1+$A22)^5)*Assumptions!$D$19)*Assumptions!$D$41/(1+WACC!$D$21)^5) -> 114211.3 | C22: =B22-$B$9 -> 43587.802 | D22: =(B22+Assumptions!$D$28)/Assumptions!$D$29 -> 4594.3256
A24: Negative 'vs Market EV' means this growth rate implies LOWER enterprise value than current market EV of ₹70,624 Cr.
A25: MCX traded at ₹2,885/share on 16 Jun 2026. Market EV = Market Cap ₹73,568 Cr − Net Cash ₹2,944 Cr = ₹70,624 Cr.
